Workbook

Sheet Qualified Leads
A1: company_name | B1: company_website | C1: recipients_name | D1: recipients_email_id | E1: mail_send_from | F1: mail_send_date | G1: mail_status | H1: lead_bucket | I1: email_domain | J1: Registration No. | K1: Registered Office Address | L1: Registered Office Telephone | M1: Registered Office Fax | N1: Registered Office City | O1: Registered Office State | P1: Registered Office Pincode | Q1: Correspondence Address | R1: Correspondence Email-Id | S1: Correspondence Telephone | T1: Correspondence Fax | U1: Correspondence City | V1: Correspondence State | W1: Correspondence Pincode | X1: Validity From | Y1: Validity To | Z1: Country | AA1: Lead Type | AB1: Multi-Registered | AC1: source_category | AE1: email_type | AF1: entity_type | AG1: data_completeness_score | AH1: lead_priority_score | AJ1: duplicate_group_key | AK1: exclusion_reason | AL1: review_reason | AM1: recommended_next_step
A2: UNIFI CAPITAL PRIVATE LIMITED | C2: Anu Kaimal | D2: compliance@unificap.com | E2: pragatichothe002 | F2: 46202 | G2: Sent | H2: A - Contact First | I2: unificap.com | J2: INP000000613 | K2: NO 11, KAKANI TOWERS,, 15 KHADER NAWAZ KHAN RD, | L2: 9109633512464 | M2: 9109633512464 | N2: CHENNAI | O2: TAMIL NADU | P2: 600006 | Q2: No11 Kakani Towers 15 Khader Nawaz Khan Road Nungambakkam Chennai 600006 | U2: CHENNAI | V2: TAMIL NADU | W2: 600006 | X2: Mar 01, 2017 | Y2: Perpetual | AA2: Portfolio Manager | AB2: No | AC2: Portfolio Manager | AE2: corporate_domain | AF2: company_firm | AG2: 100 | AH2: 100 | AJ2: DOMAIN::unificap.com | AM2: Find/verify website, run accessibility scan, then outreach
A3: WAY2WEALTH BROKERS PRIVATE LTD. | C3: Sandhya Sandhya | D3: sandhya@way2wealth.com | E3: pragatichothe002 | F3: 46202 | G3: Sent | H3: A - Contact First | I3: way2wealth.com | J3: INP000000829 | K3: RUKMINI TOWERS, 3RD and 4TH FLOOR,, NO. 3 1, PLATFORM ROAD,SHESHADRIPURAM, | L3: 9108043676869 | M3: 9108043676869 | N3: BANGALORE | O3: KARNATAKA | P3: 560020 | Q3: 3rd Floor Rukmini Towers 3 bar 1 , Sheshadripuram Bengaluru 560 020 | U3: BANGALORE | V3: KARNATAKA | W3: 560020 | X3: Jun 16, 2015 | Y3: Perpetual | AA3: Portfolio Manager | AB3: No | AC3: Portfolio Manager | AE3: corporate_domain | AF3: company_firm | AG3: 100 | AH3: 100 | AJ3: DOMAIN::way2wealth.com | AM3: Find/verify website, run accessibility scan, then outreach
A4: TRUST INVESTMENT ADVISORS PVT. LTD. | C4: Aayushi Mulasi | D4: co.pms@trustgroup.in | E4: pragatichothe002 | F4: 46202 | G4: Sent | H4: A - Contact First | I4: trustgroup.in | J4: INP000001843 | K4: 109 by 110, FIRST FLOOR, BALARAMA PREMISES CO OP SOC LTD, VILLAGE PARIGKHARI, BANDRA KURLA COMPLEX, BANDRA E | L4: 9102242245053 | M4: 9102242245053 | N4: MUMBAI | O4: MAHARASHTRA | P4: 400051 | Q4: CORPORATE OFFICE NAMAN CENTRE 1101 1102, 11TH FLOOR G BLOCK C 31 BANDRA KURLA COMPLEX BANDRA EAST | U4: MUMBAI | V4: MAHARASHTRA | W4: 400051 | X4: Oct 01, 2015 | Y4: Perpetual | AA4: Portfolio Manager | AB4: No | AC4: Portfolio Manager | AE4: corporate_domain | AF4: company_firm | AG4: 100 | AH4: 100 | AJ4: DOMAIN::trustgroup.in | AM4: Find/verify website, run accessibility scan, then outreach
A5: GLOBE CAPITAL MARKET LTD. | C5: Gautam Gupta | D5: gautamgupta@globecapital.com | E5: pragatichothe002 | F5: 46202 | G5: Sent | H5: A - Contact First | I5: globecapital.com | J5: INP000002361 | K5: 609, Ansal Bhawan, 16 K.G. Marg, Connaught Place | L5: 913041230412345 | M5: 913041230412345 | N5: NEW DELHI | O5: NATIONAL CAPITAL TERRITORY OF DELHI | P5: 110001 | Q5: 609, Ansal Bhawan, 16 K.G. Marg, Connaught Place | U5: NEW DELHI | V5: NATIONAL CAPITAL TERRITORY OF DELHI | W5: 110001 | X5: Oct 21, 2016 | Y5: Perpetual | AA5: Portfolio Manager | AB5: No | AC5: Portfolio Manager | AE5: corporate_domain | AF5: company_firm | AG5: 100 | AH5: 100 | AJ5: DOMAIN::globecapital.com | AM5: Find/verify website, run accessibility scan, then outreach
A6: ALFACCURATE ADVISORS PVT. LTD. | C6: Bhushan Koli | D6: bhushankoli@alfaccurate.com | E6: pragatichothe002 | F6: 46202 | G6: Sent | H6: A - Contact First | I6: alfaccurate.com | J6: INP000003419 | K6: 503, 5th Floor, B Wing Naman Midtown, Senapati Bapat Marg, Elphinstone Road | L6: 9122042360300 | M6: 9122042360333 | N6: MUMBAI | O6: MAHARASHTRA | P6: 400013 | Q6: 503, 5th Floor, B Wing Naman Midtown, Senapati Bapat Marg, Elphinstone Road | U6: MUMBAI | V6: MAHARASHTRA | W6: 400013 | X6: Sep 22, 2015 | Y6: Perpetual | AA6: Portfolio Manager | AB6: No | AC6: Portfolio Manager | AE6: corporate_domain | AF6: company_firm | AG6: 100 | AH6: 100 | AJ6: DOMAIN::alfaccurate.com | AM6: Find/verify website, run accessibility scan, then outreach
A7: RIGHT HORIZONS PORTFOLIO MANAGEMENT PRIVATE LIMITED | C7: Sandeep Goyal | D7: skg@righthorizons.com | G7: Sent | H7: A - Contact First | I7: righthorizons.com | J7: INP000004359 | K7: No 6 2nd Main Road Aerekere, Bannerghatta Road | L7: 910808050593005 | M7: 910808050593005 | N7: BANGALORE | O7: KARNATAKA | P7: 560076 | Q7: No 6 2nd Main Road Arekere, Bannerghatta Road | U7: BANGALORE | V7: KARNATAKA | W7: 560076 | X7: Aug 06, 2015 | Y7: Perpetual | AA7: Portfolio Manager | AB7: No | AC7: Portfolio Manager | AE7: corporate_domain | AF7: company_firm | AG7: 100 | AH7: 100 | AJ7: DOMAIN::righthorizons.com | AM7: Find/verify website, run accessibility scan, then outreach
A8: EMKAY INVESTMENT MANAGERS LIMITED | C8: Arvind Tankkar | D8: compliance@emkayglobal.com | E8: pragatichothe002 | F8: 46202 | G8: Sent | H8: A - Contact First | I8: emkayglobal.com | J8: INP000004458 | K8: The Ruby, 7th Floor,, Senapati Bapat Marg, Dadar W, | L8: 9102266299299 | M8: 9102266299299 | N8: MUMBAI | O8: MAHARASHTRA | P8: 400028 | Q8: C 6, Ground Floor, Paragon Center, P.B. Marg, Opp. Century Mills, Worli, | U8: MUMBAI | V8: MAHARASHTRA | W8: 400013 | X8: Mar 16, 2015 | Y8: Perpetual | AA8: Portfolio Manager | AB8: No | AC8: Portfolio Manager | AE8: corporate_domain | AF8: company_firm | AG8: 100 | AH8: 100 | AJ8: DOMAIN::emkayglobal.com | AM8: Find/verify website, run accessibility scan, then outreach
A9: 360 ONE Asset Management Limited | C9: Chinmayi Wagle | D9: pmscompliance@360.one | E9: pragatichothe002 | F9: 46202 | G9: Sent | H9: A - Contact First | I9: 360.one | J9: INP000004565 | K9: 6th Floor, IIFL Centre, Kamala City,, Senapati Bapat Marg, Lower Parel, | L9: 9102248765496 | M9: 9102248765496 | N9: MUMBAI | O9: MAHARASHTRA | P9: 400013 | Q9: IIFL Centre, Kamala City, Senapati Bapat Marg, Lower Parel, | U9: MUMBAI | V9: MAHARASHTRA | W9: 400013 | X9: Sep 25, 2014 | Y9: Perpetual | AA9: Portfolio Manager | AB9: No | AC9: Portfolio Manager | AE9: corporate_domain | AF9: company_firm | AG9: 100 | AH9: 100 | AJ9: DOMAIN::360.one | AM9: Find/verify website, run accessibility scan, then outreach
A10: MO Alternate Investment Advisors Private Limited | C10: Naveen Gupta | D10: compliance.moalts@motilaloswal.com | E10: pragatichothe002 | F10: 46202 | G10: Sent | H10: A - Contact First | I10: motilaloswal.com | J10: INP000004920 | K10: Motilal Oswal Tower, Rahimtullah Sayani Road, Opposite Parel ST Depot, Prabhadevi, Mumbai | L10: 91227199757083948 | M10: 91227199757083948 | N10: MUMBAI | O10: MAHARASHTRA | P10: 400025 | Q10: 10th Floor Motilal Oswal Tower Jn. of Gokhale Road, and Sayani Road Prabhadevi | U10: MUMBAI | V10: MAHARASHTRA | W10: 400025 | X10: Nov 17, 2015 | Y10: Perpetual | AA10: Portfolio Manager | AB10: No | AC10: Portfolio Manager | AE10: corporate_domain | AF10: company_firm | AG10: 100 | AH10: 100 | AJ10: DOMAIN::motilaloswal.com | AM10: Find/verify website, run accessibility scan, then outreach
A11: Buglerock Capital Private Limited | C11: Bharat Sharda | D11: compliance@buglerock.asia | E11: pragatichothe002 | F11: 46202 | G11: Sent | H11: A - Contact First | I11: buglerock.asia | J11: INP000005430 | K11: Prestige Takt, 1st Floor No 23, Kasturba Road Cross, Mahatma Gandhi Road Bangalore North Bangalore | L11: 9102269251000 | N11: BANGALORE | O11: KARNATAKA | P11: 560001 | Q11: One World Center, Tower 2, Office No 802, 8th Floor, Senapati Bapat Marg, Elphinstone Road West | U11: MUMBAI | V11: MAHARASHTRA | W11: 400013 | X11: Oct 09, 2024 | Y11: Perpetual | AA11: Portfolio Manager | AB11: No | AC11: Portfolio Manager | AE11: corporate_domain | AF11: company_firm | AG11: 100 | AH11: 100 | AJ11: DOMAIN::buglerock.asia | AM11: Find/verify website, run accessibility scan, then outreach
A12: RENAISSANCE INVESTMENT MANAGERS PRIVATE LIMITED | C12: Meghana Kashte | D12: compliance@renaissanceinvest.in | E12: pragatichothe002 | F12: 46202 | G12: Sent | H12: A - Contact First | I12: renaissanceinvest.in | J12: INP000005455 | K12: Office No. 710, 7th Floor, C Wing, Mittal Commercia Premises CHS Ltd, Off. M.V. Road. Near Mittal Estate, Marol, Andheri East | L12: 9102249711561 | N12: MUMBAI | O12: MAHARASHTRA | P12: 400059 | Q12: C 710,7th Floor, Mittal Commercia Premises CHS Ltd , Off. M.V. Road, Near Mittal Estate, Andheri | U12: MUMBAI | V12: MAHARASHTRA | W12: 400059 | X12: May 30, 2017 | Y12: Perpetual | AA12: Portfolio Manager | AB12: No | AC12: Portfolio Manager | AE12: corporate_domain | AF12: company_firm | AG12: 100 | AH12: 100 | AJ12: DOMAIN::renaissanceinvest.in | AM12: Find/verify website, run accessibility scan, then outreach
A13: EUREKA PORTFOLIO MANAGEMENT SERVICES PVT LTD | C13: VIVEK KHATOR | D13: PMS@EUREKASEC.COM | E13: pragatichothe002 | F13: 46202 | G13: Sent | H13: A - Contact First | I13: eurekasec.com | J13: INP000005740 | K13: DN 51 Merlin Infinite 11th Floor, Salt Lake Sector V | L13: 9103366280000 | M13: 9103322105184 | N13: KOLKATA | O13: WEST BENGAL | P13: 700091 | Q13: DN 51 Merlin Infinite 11th Floor, Salt Lake Sector V | U13: KOLKATA | V13: WEST BENGAL | W13: 700091 | X13: Jul 19, 2017 | Y13: Perpetual | AA13: Portfolio Manager | AB13: No | AC13: Portfolio Manager | AE13: corporate_domain | AF13: company_firm | AG13: 100 | AH13: 100 | AJ13: DOMAIN::eurekasec.com | AM13: Find/verify website, run accessibility scan, then outreach
A14: SYKES & RAY EQUITIES INDIA LIMITED | C14: Sidhant Prabhu | D14: sidhant@sre.co.in | E14: pragatichothe002 | F14: 46202 | G14: Sent | H14: A - Contact First | I14: sre.co.in | J14: INP000005795 | K14: 3rd Floor, CAMA Building, , Dalal Street, Fort | L14: 9102261937408 | M14: 9102261937408 | N14: MUMBAI | O14: MAHARASHTRA | P14: 400001 | X14: Aug 11, 2017 | Y14: Perpetual | AA14: Portfolio Manager | AB14: No | AC14: Portfolio Manager | AE14: corporate_domain | AF14: company_firm | AG14: 100 | AH14: 100 | AJ14: DOMAIN::sre.co.in | AM14: Find/verify website, run accessibility scan, then outreach
A15: Asit C Mehta Investment Interrmediates Limited | C15: Jaideep Vaidya | D15: complianceofficer@acm.co.in | E15: pragatichothe002 | F15: 46202 | G15: Sent | H15: A - Contact First | I15: acm.co.in | J15: INP000005801 | K15: PANTOMATH NUCLEUS HOUSE, SAKI VIHAR ROAD ANDHERI E | L15: 02202228583333 | N15: MUMBAI | O15: MAHARASHTRA | P15: 400072 | Q15: PANTOMATH NUCLEUS HOUSE, SAKI VIHAR ROAD ANDHERI E | U15: MUMBAI | V15: MAHARASHTRA | W15: 400072 | X15: May 29, 2024 | Y15: Perpetual | AA15: Portfolio Manager | AB15: Yes | AC15: Portfolio Manager | AE15: corporate_domain | AF15: company_firm | AG15: 100 | AH15: 100 | AJ15: DOMAIN::acm.co.in | AM15: Find/verify website, run accessibility scan, then outreach
A16: 360 ONE PORTFOLIO MANAGERS LIMITED | C16: Purva Joshi | D16: regcompliance@iiflw.com | E16: pragatichothe002 | F16: 46202 | G16: Sent | H16: A - Contact First | I16: iiflw.com | J16: INP000005874 | K16: IIFL Centre, Kamala City, Senapati Bapat Marg, Lower Parel West | L16: 9102248765496 | M16: 9102248765496 | N16: MUMBAI | O16: MAHARASHTRA | P16: 400013 | Q16: IIFL Centre, Kamala City, Senapati Bapat Marg, Lower Parel, | U16: MUMBAI | V16: MAHARASHTRA | W16: 400013 | X16: Nov 28, 2017 | Y16: Perpetual | AA16: Portfolio Manager | AB16: No | AC16: Portfolio Manager | AE16: corporate_domain | AF16: company_firm | AG16: 100 | AH16: 100 | AJ16: DOMAIN::iiflw.com | AM16: Find/verify website, run accessibility scan, then outreach
A17: GREEN PORTFOLIO PRIVATE LIMITED | C17: Tamana Mahnot | D17: cs@greenportfolio.co | E17: pragatichothe002 | F17: 46202 | G17: Sent | H17: A - Contact First | I17: greenportfolio.co | J17: INP000006022 | K17: Unit No. 207, 2nd Floor, JMD Empire Square, Mehrauli Gurgaon Road, A Block, DLF Phase - I, Sector 28, Sikanderpur Ghosi | L17: 0919782027569 | M17: 0919782027569 | N17: GURUGRAM | O17: HARYANA | P17: 122002 | Q17: Farm No. 5, 1645, Kanawani Village, Indirapuram, Ghaziabad | U17: GHAZIABAD | V17: UTTAR PRADESH | W17: 201014 | X17: Jun 11, 2018 | Y17: Perpetual | AA17: Portfolio Manager | AB17: Yes | AC17: Portfolio Manager | AE17: corporate_domain | AF17: company_firm | AG17: 100 | AH17: 100 | AJ17: DOMAIN::greenportfolio.co | AM17: Find/verify website, run accessibility scan, then outreach
A18: Fort Capital Investment Advisory Private Limited | C18: NIDHI KAJI | D18: compliance@fortcapital.in | E18: pragatichothe002 | F18: 46202 | G18: Sent | H18: A - Contact First | I18: fortcapital.in | J18: INP000006031 | K18: 304, 3rd Floor, Hubtown Solaris,, N. S. Phadke Marg, Near Flyover Bridge, Andheri East, | L18: 9102269973600 | M18: 9102269973600 | N18: MUMBAI | O18: MAHARASHTRA | P18: 400069 | Q18: 304, 3rd Floor, Hubtown Solaris, N. S. Phadke Marg, Near Flyover Bridge, Andheri East, | U18: MUMBAI | V18: MAHARASHTRA | W18: 400069 | X18: Jun 13, 2018 | Y18: Perpetual | AA18: Portfolio Manager | AB18: No | AC18: Portfolio Manager | AE18: corporate_domain | AF18: company_firm | AG18: 100 | AH18: 100 | AJ18: DOMAIN::fortcapital.in | AM18: Find/verify website, run accessibility scan, then outreach
A19: Credent Asset Management Services Private Limited | C19: Preeti Sethi | D19: compliance@credentglobal.com | E19: pragatichothe002 | F19: 46202 | G19: Sent | H19: A - Contact First | I19: credentglobal.com | J19: INP000006101 | K19: 306, B2, Shubham Centre, Cardinal Gracious Road, Chakala, Andheri East | L19: 9102268452001 | M19: 9102268452001 | N19: MUMBAI | O19: MAHARASHTRA | P19: 400099 | Q19: Unit No. 609, 6th Floor, C Wing, One BKC, G Block, Bandra Kurla Complex, Bandra East | U19: MUMBAI | V19: MAHARASHTRA | W19: 400051 | X19: Dec 18, 2023 | Y19: Perpetual | AA19: Portfolio Manager | AB19: Yes | AC19: Portfolio Manager | AE19: corporate_domain | AF19: company_firm | AG19: 100 | AH19: 100 | AJ19: DOMAIN::credentglobal.com | AM19: Find/verify website, run accessibility scan, then outreach
A20: Spark Asia Impact Managers Private Limited | C20: Amrita Pillai | D20: eam.compliance@sparkcapital.in | E20: pragatichothe002 | F20: 46202 | G20: Sent | H20: A - Contact First | I20: sparkcapital.in | J20: INP000006235 | K20: No. 1, 3rd Floor, First Crescent Park Road, Gandhi Nagar, Adyar | L20: 9104469250000 | M20: 9104469250000 | N20: CHENNAI | O20: TAMIL NADU | P20: 600020 | Q20: No. 99, 2nd Floor, Senans Squaree, Santhome High Road, Santhome | U20: CHENNAI | V20: TAMIL NADU | W20: 600028 | X20: Nov 14, 2018 | Y20: Perpetual | AA20: Portfolio Manager | AB20: No | AC20: Portfolio Manager | AE20: corporate_domain | AF20: company_firm | AG20: 100 | AH20: 100 | AJ20: DOMAIN::sparkcapital.in | AM20: Find/verify website, run accessibility scan, then outreach
A21: Entrust Family Office Investment Advisors Private Limited | C21: Pradeep A N | D21: compliance@entrust.co.in | E21: pragatichothe002 | F21: 46202 | G21: Sent | H21: A - Contact First | I21: entrust.co.in | J21: INP000006314 | K21: No.24, 4th Floor, 1st Cross, Magrath Road, | L21: 9108041479777 | M21: 9108041479777 | N21: BANGALORE | O21: KARNATAKA | P21: 560025 | Q21: No.24,4th Floor, 1st Cross, Magrath Road | U21: BANGALORE | V21: KARNATAKA | W21: 560025 | X21: Dec 11, 2018 | Y21: Perpetual | AA21: Portfolio Manager | AB21: No | AC21: Portfolio Manager | AE21: corporate_domain | AF21: company_firm | AG21: 100 | AH21: 100 | AJ21: DOMAIN::entrust.co.in | AM21: Find/verify website, run accessibility scan, then outreach
A22: CONCEPT INVESTWELL PRIVATE LIMITED | C22: NIRAV DESAI | D22: compliance@conceptinvestwell.com | E22: pragatichothe002 | F22: 46202 | G22: Sent | H22: A - Contact First | I22: conceptinvestwell.com | J22: INP000006323 | K22: 10 A UNION HEIGHTS , MAHARANA PRATAP ROAD, RAHUL RAJ MALL LANE,DUMAS ROAD | L22: 9102612206026 | M22: 9102612206026 | N22: SURAT | O22: GUJARAT | P22: 395007 | Q22: 10 A UNION HEIGHTS, MAHARANA PRATAP ROAD, RAHUL RAJJ MALL, | U22: SURAT | V22: GUJARAT | W22: 395007 | X22: Dec 13, 2018 | Y22: Perpetual | AA22: Portfolio Manager | AB22: No | AC22: Portfolio Manager | AE22: corporate_domain | AF22: company_firm | AG22: 100 | AH22: 100 | AJ22: DOMAIN::conceptinvestwell.com | AM22: Find/verify website, run accessibility scan, then outreach
A23: WEALTH FIRST PORTFOLIO MANAGERS LIMITED | C23: NIKHIL JAIN | D23: nikhil@wealthfirst.biz | E23: pragatichothe002 | F23: 46202 | G23: Sent | H23: A - Contact First | I23: wealthfirst.biz | J23: INP000006332 | K23: CAPITOL HOUSE, 10 PARAS-II, NEAR CAMPUS CORNER,, PRAHALADNAGAR, ANANDNAGAR, ABD 380015 | L23: 07907940240000 | M23: 07907940240000 | N23: AHMEDABAD | O23: GUJARAT | P23: 380015 | Q23: CAPITOL HOUSE, 10 PARAS-II, NEAR CAMPUS CORNER, PRAHALADNAGAR, ANANDNAGAR, ABD 380015 | U23: AHMEDABAD | V23: GUJARAT | W23: 380015 | X23: Dec 21, 2018 | Y23: Perpetual | AA23: Portfolio Manager | AB23: No | AC23: Portfolio Manager | AE23: corporate_domain | AF23: company_firm | AG23: 100 | AH23: 100 | AJ23: DOMAIN::wealthfirst.biz | AM23: Find/verify website, run accessibility scan, then outreach
A24: M/S.ASTEYA INVESTMENT MANAGERS LLP, | C24: Poonam Rawal | D24: poonam.rawal@asteyaglobal.com | E24: pragatichothe002 | F24: 46202 | G24: Sent | H24: A - Contact First | I24: asteyaglobal.com | J24: INP000006536 | K24: Office no.110, 1st floor, Keshava Building, Plot No C-5,, E Block, Bandra Kurla Complex, Bandra East | L24: 9102226514252 | M24: 9102226514252 | N24: MUMBAI | O24: MAHARASHTRA | P24: 400051 | Q24: Office no.110, 1st floor, Keshava Building, Plot No C-5, E Block, Bandra Kurla Complex, Bandra East | U24: MUMBAI | V24: MAHARASHTRA | W24: 400051 | X24: Apr 01, 2019 | Y24: Perpetual | AA24: Portfolio Manager | AB24: No | AC24: Portfolio Manager | AE24: corporate_domain | AF24: company_firm | AG24: 100 | AH24: 100 | AJ24: DOMAIN::asteyaglobal.com | AM24: Find/verify website, run accessibility scan, then outreach
A25: COMPOUND EVERYDAY CAPITAL MANAGEMENT LLP | C25: Arpit Parmar | D25: arpit.parmar@cedcapital.in | E25: pragatichothe002 | F25: 46202 | G25: Sent | H25: A - Contact First | I25: cedcapital.in | J25: INP000006633 | K25: Sakar Bhawan, 2nd Floor, ATM Side, 21/4 Ratlam Kothi Main Road, Above Federal Bank | L25: 9107312510070 | M25: 9107312510070 | N25: INDORE | O25: MADHYA PRADESH | P25: 452001 | Q25: Sakar Bhawan, 2nd Floor, ATM Side, 21/4 Ratlam Kothi Main Road, Above Federal Bank | U25: INDORE | V25: MADHYA PRADESH | W25: 452001 | X25: Apr 11, 2019 | Y25: Perpetual | AA25: Portfolio Manager | AB25: No | AC25: Portfolio Manager | AE25: corporate_domain | AF25: company_firm | AG25: 100 | AH25: 100 | AJ25: DOMAIN::cedcapital.in | AM25: Find/verify website, run accessibility scan, then outreach
A26: First Global Finance Pvt Ltd | C26: Mahima Vyas | D26: compliance@firstglobal.in | E26: pragatichothe002 | F26: 46202 | G26: Sent | H26: A - Contact First | I26: firstglobal.in | J26: INP000006697 | K26: 1st Floor, Ratnam Square, Plot No. 38 39, Sector 19A, Sector 19A, Vashi, | L26: 91222261166525 | N26: NAVI MUMBAI | O26: MAHARASHTRA | P26: 110001 | Q26: Ratnam Square, Plot No. 38 39, Sector 19A, Vashi | U26: NAVI MUMBAI | V26: MAHARASHTRA | W26: 400703 | X26: Apr 23, 2019 | Y26: Perpetual | AA26: Portfolio Manager | AB26: No | AC26: Portfolio Manager | AE26: corporate_domain | AF26: company_firm | AG26: 100 | AH26: 100 | AJ26: DOMAIN::firstglobal.in | AM26: Find/verify website, run accessibility scan, then outreach
A27: SMC Global Securities Limited | C27: Vikas Sethi | D27: vikassethi@smcindiaonline.com | E27: pragatichothe002 | F27: 46202 | G27: Sent | H27: A - Contact First | I27: smcindiaonline.com | J27: INP000006703 | K27: 11/6B, Shanti Chambers Pusa Road, New Delhi | L27: 91111130111000 | M27: 91111130111000 | N27: NEW DELHI | O27: NATIONAL CAPITAL TERRITORY OF DELHI | P27: 110005 | Q27: 11/6B, Shanti Chambers Pusa Road, New Delhi | U27: NEW DELHI | V27: NATIONAL CAPITAL TERRITORY OF DELHI | W27: 110005 | X27: Apr 26, 2019 | Y27: Perpetual | AA27: Portfolio Manager | AB27: No | AC27: Portfolio Manager | AE27: corporate_domain | AF27: company_firm | AG27: 100 | AH27: 100 | AJ27: DOMAIN::smcindiaonline.com | AM27: Find/verify website, run accessibility scan, then outreach
A28: TURTLE WEALTH MANAGEMENT PVT. LTD. | C28: Vibhati Arya | D28: vibhati@turtlewealth.in | E28: pragatichothe002 | F28: 46202 | G28: Sent | H28: A - Contact First | I28: turtlewealth.in | J28: INP000006758 | K28: 1001 Rajhans Montessa, B/S Le Meridien Hotel , Dumas Road, Magdalla | L28: 91919925238849 | M28: 91919925238849 | N28: SURAT | O28: GUJARAT | P28: 395007 | Q28: 1001 Rajhans Montessa, B/S Le Meridien Hotel , Dumas Road, Magdalla | U28: SURAT | V28: GUJARAT | W28: 395007 | X28: May 08, 2019 | Y28: Perpetual | AA28: Portfolio Manager | AB28: No | AC28: Portfolio Manager | AE28: corporate_domain | AF28: company_firm | AG28: 100 | AH28: 100 | AJ28: DOMAIN::turtlewealth.in | AM28: Find/verify website, run accessibility scan, then outreach
A29: JAINAM BROKING LIMITED | C29: Vidhi Parikh | D29: vidhi.parikh@jainam.in | E29: pragatichothe002 | F29: 46202 | G29: Sent | H29: A - Contact First | I29: jainam.in | J29: INP000006785 | K29: JAINAM HOUSE, NEW PASSPORT OFFICE ROAD,, PIPLOD | L29: 09102616725556 | M29: 09102616725556 | N29: SURAT | O29: GUJARAT | P29: 395007 | Q29: JAINAM HOUSE, NEW PASSPORT OFFICE ROAD, PIPLOD | U29: SURAT | V29: GUJARAT | W29: 395007 | X29: Jun 27, 2019 | Y29: Perpetual | AA29: Portfolio Manager | AB29: Yes | AC29: Portfolio Manager | AE29: corporate_domain | AF29: company_firm | AG29: 100 | AH29: 100 | AJ29: DOMAIN::jainam.in | AM29: Find/verify website, run accessibility scan, then outreach
A30: Altlnvest Capital Advisors Private Limited | C30: Hashim Khan | D30: invest@propsharecapital.com | E30: pragatichothe002 | F30: 46202 | G30: Sent | H30: A - Contact First | I30: propsharecapital.com | J30: INP000006800 | K30: 10th Floor, SKAV Seethalakshmi, 21/22, Kasturba Road | L30: 9108041692999 | N30: BANGALORE | O30: KARNATAKA | P30: 560001 | Q30: 10th Floor, SKAV Seethalakshmi, 21/22, Kasturba Road | U30: BANGALORE | V30: KARNATAKA | W30: 560001 | X30: Jun 28, 2019 | Y30: Perpetual | AA30: Portfolio Manager | AB30: No | AC30: Portfolio Manager | AE30: corporate_domain | AF30: company_firm | AG30: 100 | AH30: 100 | AJ30: DOMAIN::propsharecapital.com | AM30: Find/verify website, run accessibility scan, then outreach
A31: Julius Baer Wealth Advisors India Private Limited | C31: Purva Joshi | D31: purva.joshi@juliusbaer.com | E31: pragatichothe002 | F31: 46202 | G31: Sent | H31: A - Contact First | I31: juliusbaer.com | J31: INP000007012 | K31: Altimus, 2501, 25th level,, Pandurang Budhkar Marg, Worli | L31: 9102261760184 | M31: 9102261760184 | N31: MUMBAI | O31: MAHARASHTRA | P31: 400018 | Q31: Altimus, 2501, 25th level, Pandurang Budhkar Marg, Worli | U31: MUMBAI | V31: MAHARASHTRA | W31: 400018 | X31: Jul 14, 2020 | Y31: Perpetual | AA31: Portfolio Manager | AB31: No | AC31: Portfolio Manager | AE31: corporate_domain | AF31: company_firm | AG31: 100 | AH31: 100 | AJ31: DOMAIN::juliusbaer.com | AM31: Find/verify website, run accessibility scan, then outreach
A32: Purnartha Investment Advisers Pvt.Ltd. | C32: AMOL DEO | D32: amol.d@purnartha.com | E32: pragatichothe002 | F32: 46202 | G32: Sent | H32: A - Contact First | I32: purnartha.com | J32: INP000007021 | K32: Rachna Bungalow Dr Kelkar Road, Off Karve Road Erandwane | L32: 9102049127100 | N32: PUNE | O32: MAHARASHTRA | P32: 411004 | Q32: Rachna Bungalow Dr Kelkar Road, Off Karve Road Erandwane | U32: PUNE | V32: MAHARASHTRA | W32: 411004 | X32: Jul 23, 2020 | Y32: Perpetual | AA32: Portfolio Manager | AB32: Yes | AC32: Portfolio Manager | AE32: corporate_domain | AF32: company_firm | AG32: 100 | AH32: 100 | AJ32: DOMAIN::purnartha.com | AM32: Find/verify website, run accessibility scan, then outreach
A33: EQUIRUS WEALTH PRIVATE LIMITED | C33: JINESHA MEHTA | D33: equirus_compliance@equirus.com | E33: pragatichothe002 | F33: 46202 | G33: Sent | H33: A - Contact First | I33: equirus.com | J33: INP000007076 | K33: A1303MarathonFuturexMafatlalMillsCompound , NMJOSHIMARGLOWERPAREL | L33: 9107961909586 | M33: 9107961909586 | N33: MUMBAI | O33: MAHARASHTRA | P33: 400013 | Q33: 3RD FLOOR HOUSE NO 9 MAGNET CORPORATE PARK, B/H INTAS SOLA BRIDGE S G HIGHWAY THALTEJ | U33: AHMEDABAD | V33: GUJARAT | W33: 380054 | X33: Oct 06, 2020 | Y33: Perpetual | AA33: Portfolio Manager | AB33: No | AC33: Portfolio Manager | AE33: corporate_domain | AF33: company_firm | AG33: 100 | AH33: 100 | AJ33: DOMAIN::equirus.com | AM33: Find/verify website, run accessibility scan, then outreach
A34: CKREDENCE WEALTH MANAGEMENT PRIVATE LIMITED | C34: PRAKASHKUMAR MAVANI | D34: PRAKASH.MAVANI@CKREDENCEWEALTH.COM | E34: pragatichothe002 | F34: 46202 | G34: Sent | H34: A - Contact First | I34: ckredencewealth.com | J34: INP000007164 | K34: 901,902,903, International Wealth Center, VIP Road, Vesu | L34: 9102614084406 | M34: 9102614084406 | N34: SURAT | O34: GUJARAT | P34: 395007 | X34: Feb 26, 2021 | Y34: Perpetual | AA34: Portfolio Manager | AB34: Yes | AC34: Portfolio Manager | AE34: corporate_domain | AF34: company_firm | AG34: 100 | AH34: 100 | AJ34: DOMAIN::ckredencewealth.com | AM34: Find/verify website, run accessibility scan, then outreach
A35: Arthya Wealth and Investments Pvt Ltd | C35: Nasreen Qureshi | D35: nasreen@arthyawealth.com | E35: pragatichothe002 | F35: 46202 | G35: Sent | H35: A - Contact First | I35: arthyawealth.com | J35: INP000007225 | K35: 712 THE SUMMIT BUSINESS BAY, 7th Floor, Near Western Express Highway, Off Andheri Kurla Road, Andheri East | L35: 910009819793096 | M35: 910009819793096 | N35: MUMBAI | O35: MAHARASHTRA | P35: 400069 | Q35: 712 THE SUMMIT BUSINESS BAY, 7th Floor, Near Western Express Highway, Off Andheri Kurla Road, Andheri East | U35: MUMBAI | V35: MAHARASHTRA | W35: 400069 | X35: Jun 09, 2021 | Y35: Perpetual | AA35: Portfolio Manager | AB35: No | AC35: Portfolio Manager | AE35: corporate_domain | AF35: company_firm | AG35: 100 | AH35: 100 | AJ35: DOMAIN::arthyawealth.com | AM35: Find/verify website, run accessibility scan, then outreach
A36: Pioneer Client Associates Private Limited | C36: Rakesh Khanna | D36: rakeshkhanna@clientassociates.com | E36: pragatichothe002 | F36: 46202 | G36: Sent | H36: A - Contact First | I36: clientassociates.com | J36: INP100007231 | K36: 2nd Floor, Block B, Vatika Towers, Golf Course Road,, Sector 54 | L36: 9112404995400 | N36: GURGAON | O36: HARYANA | P36: 122002 | Q36: 2nd Floor, Block B, Vatika Towers, Golf Course Road, Sector 54 | U36: GURGAON | V36: HARYANA | W36: 122002 | X36: Jun 29, 2021 | Y36: Perpetual | AA36: Portfolio Manager | AB36: No | AC36: Portfolio Manager | AE36: corporate_domain | AF36: company_firm | AG36: 100 | AH36: 100 | AJ36: DOMAIN::clientassociates.com | AM36: Find/verify website, run accessibility scan, then outreach
A37: DEZERV INVESTMENTS PRIVATE LIMITED | C37: Kavita Khatri | D37: kavita.khatri@dezerv.in | E37: pragatichothe001 | F37: 46202 | G37: Sent | H37: A - Contact First | I37: dezerv.in | J37: INP000007377 | K37: Unit No. 301, Trade Centre, Bandra East | L37: 910009167830754 | M37: 910009167830754 | N37: MUMBAI | O37: MAHARASHTRA | P37: 400051 | Q37: Unit No. 301, Trade Centre, Bandra East | U37: MUMBAI | V37: MAHARASHTRA | W37: 400051 | X37: Mar 24, 2022 | Y37: Perpetual | AA37: Portfolio Manager | AB37: No | AC37: Portfolio Manager | AE37: corporate_domain | AF37: company_firm | AG37: 100 | AH37: 100 | AJ37: DOMAIN::dezerv.in | AM37: Find/verify website, run accessibility scan, then outreach
A38: WhiteOak Capital Asset Management Limited | C38: Prannav Shah | D38: prannav.shah@whiteoakinvestors.com | E38: pragatichothe001 | F38: 46202 | G38: Sent | H38: A - Contact First | I38: whiteoakinvestors.com | J38: INP000007766 | K38: Unit No. B4, 6th Floor, Cnergy, Appasaheb Marathe Marg, Prabhadevi | L38: 00002269463518 | M38: 00002269463518 | N38: MUMBAI | O38: MAHARASHTRA | P38: 400025 | Q38: Unit No. B4, 6th Floor, Cnergy, Appasaheb Marathe Marg, Prabhadevi | U38: MUMBAI | V38: MAHARASHTRA | W38: 400025 | X38: Jan 13, 2023 | Y38: Perpetual | AA38: Portfolio Manager | AB38: No | AC38: Portfolio Manager | AE38: corporate_domain | AF38: company_firm | AG38: 100 | AH38: 100 | AJ38: DOMAIN::whiteoakinvestors.com | AM38: Find/verify website, run accessibility scan, then outreach
A39: SINCERE SYNDICATION AND CORPORATE SERVICES LLP | C39: Sudharshan S | D39: Sudarshan@sinceresyndication.com | E39: pragatichothe001 | F39: 46202 | G39: Sent | H39: A - Contact First | I39: sinceresyndication.com | J39: INP200007803 | K39: Adwave Towers, 3rd Floor, Block A,, No.9, South Boag Road, T. Nagar | L39: 004445546075 | M39: 004445546075 | N39: CHENNAI | O39: TAMIL NADU | P39: 600017 | Q39: Adwave Towers, 3rd Floor, Block A, No.9, South Boag Road, T. Nagar | U39: CHENNAI | V39: TAMIL NADU | W39: 600017 | X39: Jan 31, 2023 | Y39: Perpetual | AA39: Portfolio Manager | AB39: Yes | AC39: Portfolio Manager | AE39: corporate_domain | AF39: company_firm | AG39: 100 | AH39: 100 | AJ39: DOMAIN::sinceresyndication.com | AM39: Find/verify website, run accessibility scan, then outreach
A40: Waterfield Financial and Investment Advisors Private Limited | C40: Shilpa Dadhich | D40: shilpa.dadhich@waterfieldadvisors.com | E40: pragatichothe001 | F40: 46202 | G40: Sent | H40: A - Contact First | I40: waterfieldadvisors.com | J40: INP000007818 | K40: 142 Maker Chamber VI , 220 Jamnalal Bajaj Marg Nariman Point | L40: 000919987538394 | M40: 000919987538394 | N40: MUMBAI | O40: MAHARASHTRA | P40: 400021 | Q40: 142 Maker Chamber VI , 220 Jamnalal Bajaj Marg Nariman Point | U40: MUMBAI | V40: MAHARASHTRA | W40: 400021 | X40: Feb 14, 2023 | Y40: Perpetual | AA40: Portfolio Manager | AB40: No | AC40: Portfolio Manager | AE40: corporate_domain | AF40: company_firm | AG40: 100 | AH40: 100 | AJ40: DOMAIN::waterfieldadvisors.com | AM40: Find/verify website, run accessibility scan, then outreach
...

Sheet Need Manual Review
A1: Name | B1: Registration No. | C1: Contact Person | D1: Registered Office Address | E1: Registered Office Email-Id | F1: Registered Office Telephone | G1: Registered Office Fax | H1: Registered Office City | I1: Registered Office State | J1: Registered Office Pincode | K1: Correspondence Address | L1: Correspondence Email-Id | M1: Correspondence Telephone | N1: Correspondence Fax | O1: Correspondence City | P1: Correspondence State | Q1: Correspondence Pincode | R1: Validity From | S1: Validity To | T1: Country | U1: Lead Type | V1: Multi-Registered | W1: source_category | X1: email_domain | Y1: email_type | Z1: entity_type | AA1: data_completeness_score | AB1: lead_priority_score | AC1: lead_bucket | AD1: duplicate_group_key | AE1: exclusion_reason | AF1: review_reason | AG1: recommended_next_step
A2: Spark PWM Private Limited | B2: INP200007274 | C2: Anupam Mohaney | D2: No. 1, 3rd Floor, First Crescent Park Road, , Gandhi Nagar, Adyar | E2: pwm.compliance@sparkcapital.in | F2: 9104469250000 | G2: 9104469250000 | H2: CHENNAI | I2: TAMIL NADU | J2: 600020 | K2: No. 1, 3rd Floor, First Crescent Park Road, , Gandhi Nagar, Adyar | O2: CHENNAI | P2: TAMIL NADU | Q2: 600020 | R2: Sep 14, 2021 | S2: Perpetual | U2: Portfolio Manager | V2: Yes | W2: Portfolio Manager | X2: sparkcapital.in | Y2: corporate_domain | Z2: company_firm | AA2: 100 | AB2: 100 | AC2: A - Contact First | AD2: DOMAIN::sparkcapital.in | AF2: possible_duplicate_or_multi_category_entity | AG2: Manually verify website and contact details before outreach
A3: Waterfield Fund Managers Private Limited | B3: INP000008288 | C3: Shivani Sharma | D3: 142 Maker Chamber VI 220 , Jamnalal Bajaj Marg Nariman Point | E3: shivani.sharma@waterfieldadvisors.com | F3: 00919987358249 | G3: 00919987358249 | H3: MUMBAI | I3: MAHARASHTRA | J3: 400021 | K3: Unit no 07 7th office level equivalent to the 14th floor Avighna House, 82 Annie Besant Road Worli | O3: MUMBAI | P3: MAHARASHTRA | Q3: 400018 | R3: Sep 07, 2023 | S3: Perpetual | U3: Portfolio Manager | V3: No | W3: Portfolio Manager | X3: waterfieldadvisors.com | Y3: corporate_domain | Z3: company_firm | AA3: 100 | AB3: 100 | AC3: A - Contact First | AD3: DOMAIN::waterfieldadvisors.com | AF3: possible_duplicate_or_multi_category_entity | AG3: Manually verify website and contact details before outreach
A4: 360 ONE Alternates Asset Management Limited | B4: INP000008640 | C4: Chirag Gandhi | D4: 360 ONE Centre, Kamala City, Lower Parel West | E4: pmscompliance@360.one | F4: 9102248765600 | G4: 9102248765600 | H4: MUMBAI | I4: MAHARASHTRA | J4: 400013 | K4: 360 ONE Centre, Kamala City, Lower Parel West | O4: MUMBAI | P4: MAHARASHTRA | Q4: 400013 | R4: Mar 27, 2024 | S4: Perpetual | U4: Portfolio Manager | V4: No | W4: Portfolio Manager | X4: 360.one | Y4: corporate_domain | Z4: company_firm | AA4: 100 | AB4: 100 | AC4: A - Contact First | AD4: DOMAIN::360.one | AF4: possible_duplicate_or_multi_category_entity | AG4: Manually verify website and contact details before outreach
A5: Spark Fund Advisors LLP | B5: INP000008835 | C5: Amrita Pillai | D5: No. 1, 3rd Floor, First Crescent Park Road,, Gandhi Nagar, Adyar, | E5: compliance@sparkcapital.in | F5: 9104469250000 | G5: 9104469250000 | H5: CHENNAI | I5: TAMIL NADU | J5: 600020 | K5: No. 1, 3rd Floor, First Crescent Park Road, Gandhi Nagar, Adyar, | O5: CHENNAI | P5: TAMIL NADU | Q5: 600020 | R5: Jul 22, 2024 | S5: Perpetual | U5: Portfolio Manager | V5: No | W5: Portfolio Manager | X5: sparkcapital.in | Y5: corporate_domain | Z5: company_firm | AA5: 100 | AB5: 100 | AC5: A - Contact First | AD5: DOMAIN::sparkcapital.in | AF5: possible_duplicate_or_multi_category_entity | AG5: Manually verify website and contact details before outreach
A6: ASTEYA INVESTMENT MANAGERS LLP | B6: INA000000276 | C6: MR. ARUN BHAL | D6: 4G/4H, SIDDHIVINAYAK CHAMBERS,, 643, GANDHI NAGAR, OPP. MIG CLUB, BANDRA EAST, MUMBAI | E6: arun.bhal@asteyaglobal.com | F6: 2226514252 | G6: 2226514252 | H6: MUMBAI | I6: MAHARASHTRA | J6: 400051 | K6: 4G/4H, Siddhivinayak Chambers, 643, Gandhi Nagar, Opp. MIG Club, Bandra East, Mumbai | O6: MUMBAI | P6: MAHARASHTRA | Q6: 400051 | R6: Nov 21, 2013 | S6: Perpetual | U6: Investment Adviser | V6: No | W6: Investment Adviser | X6: asteyaglobal.com | Y6: corporate_domain | Z6: company_firm | AA6: 100 | AB6: 97 | AC6: A - Contact First | AD6: DOMAIN::asteyaglobal.com | AF6: possible_duplicate_or_multi_category_entity | AG6: Manually verify website and contact details before outreach
A7: ASK Wealth Advisors Private Limited | B7: INA000000532 | C7: Vijay Shah | D7: Birla Aurora, 16 Level, Office Floor 9 , Dr. Annie Besant Road, Worli | E7: askwa_compliance@askwealthadvisors.com | F7: 0919930235443 | G7: 0919930235443 | H7: MUMBAI | I7: MAHARASHTRA | J7: 400030 | K7: 28th floor, 2803, 2804 and 2805, One Lodha Place, Senapati Bapat Marg, Lower Parel | O7: MUMBAI | P7: MAHARASHTRA | Q7: 400013 | R7: Mar 31, 2023 | S7: Perpetual | U7: Investment Adviser | V7: Yes | W7: Investment Adviser | X7: askwealthadvisors.com | Y7: corporate_domain | Z7: company_firm | AA7: 100 | AB7: 97 | AC7: A - Contact First | AD7: DOMAIN::askwealthadvisors.com | AF7: possible_duplicate_or_multi_category_entity | AG7: Manually verify website and contact details before outreach
A8: Purnartha Investment Advisers Pvt.Ltd. | B8: INA000000672 | C8: Chandani Saruparia | D8: Rachna Bunglow,Near Dr.Shyamrao Kalmadi HighSchool,, Dr.Ketkar Road, Off Karve Road, Erandwane | E8: chandani.s@purnartha.com | F8: 919993969339 | G8: 919993969339 | H8: PUNE | I8: MAHARASHTRA | J8: 411004 | K8: Rachna Bunglow,Near Dr.Shyamrao Kalmadi HighSchool, Dr.Ketkar Road, Off Karve Road, Erandwane | O8: PUNE | P8: MAHARASHTRA | Q8: 411004 | R8: Dec 26, 2013 | S8: Perpetual | U8: Investment Adviser | V8: Yes | W8: Investment Adviser | X8: purnartha.com | Y8: corporate_domain | Z8: company_firm | AA8: 100 | AB8: 97 | AC8: A - Contact First | AD8: DOMAIN::purnartha.com | AF8: possible_duplicate_or_multi_category_entity | AG8: Manually verify website and contact details before outreach
A9: 360 ONE Investment Adviser and Trustee Services Limited | B9: INA000000888 | C9: Jatin Sanghani | D9: IIFL Centre, Kamala Mills, Senapati Bapat Marg, Lower Parel | E9: 360.compliance@360.one | F9: 0919769974254 | G9: 0919769974254 | H9: MUMBAI | I9: MAHARASHTRA | J9: 400013 | K9: 7th Floor,IIFL Centre, Kamala Mills Compound,Senapati Bapat Marg,Lower Parel (West), | O9: MUMBAI | P9: MAHARASHTRA | Q9: 400013 | R9: Jan 22, 2014 | S9: Perpetual | U9: Investment Adviser | V9: No | W9: Investment Adviser | X9: 360.one | Y9: corporate_domain | Z9: company_firm | AA9: 100 | AB9: 97 | AC9: A - Contact First | AD9: DOMAIN::360.one | AF9: possible_duplicate_or_multi_category_entity | AG9: Manually verify website and contact details before outreach
A10: WATERFIELD FINANCIAL AND INVESTMENT ADVISORS PRIVATE LIMITED | B10: INA000001811 | C10: Vivek Rajaraman | D10: 142, 14TH FLOOR, MAKER CHAMBERS, VI, 220, JAMNALAL BAJAJ MARG, NARIMAN POINT | E10: principal.officer@waterfieldadvisors.com | F10: 919987538394 | G10: 919987538394 | I10: MAHARASHTRA | J10: 400021 | K10: 7 Avighna House 82 Dr Annie Besant Road, Worli Naka Siddharth Nagar Worli Mumbai | O10: MUMBAI | P10: MAHARASHTRA | Q10: 400018 | R10: Jun 02, 2014 | S10: Perpetual | U10: Investment Adviser | V10: No | W10: Investment Adviser | X10: waterfieldadvisors.com | Y10: corporate_domain | Z10: company_firm | AA10: 100 | AB10: 97 | AC10: A - Contact First | AD10: DOMAIN::waterfieldadvisors.com | AF10: possible_duplicate_or_multi_category_entity | AG10: Manually verify website and contact details before outreach
A11: Julius Baer Wealth Advisors (India) Private Limited | B11: INA000003130 | C11: Naynesh Sampat | D11: Altimus, 2501, 25th Level, Pandurang Budhkar Marg, Worli | E11: naynesh.sampat@juliusbaer.com | F11: 91009823420785 | G11: 91009823420785 | H11: MUMBAI | I11: MAHARASHTRA | J11: 400018 | K11: Altimus, 2501, 25th Level, Pandurang Budhkar Marg, Worli | O11: MUMBAI | P11: MAHARASHTRA | Q11: 400018 | R11: Jun 30, 2015 | S11: Perpetual | U11: Investment Adviser | V11: No | W11: Investment Adviser | X11: juliusbaer.com | Y11: corporate_domain | Z11: company_firm | AA11: 100 | AB11: 97 | AC11: A - Contact First | AD11: DOMAIN::juliusbaer.com | AF11: possible_duplicate_or_multi_category_entity | AG11: Manually verify website and contact details before outreach
A12: EQUENTIS WEALTH ADVISORY SERVICES LIMITED | B12: INA000003874 | C12: Rakesh Gupta | D12: A-603, Marathon Futurex, Mafatlal Mills Compound,, N. M. Joshi Marg, Lower Parel, | E12: compliance@equentis.com | F12: 919152000163 | G12: 919152000163 | H12: MUMBAI | I12: MAHARASHTRA | J12: 400013 | K12: A-603, Marathon Futurex, Mafatlal Mills Compound, N. M. Joshi Marg, Lower Parel, | O12: MUMBAI | P12: MAHARASHTRA | Q12: 400013 | R12: Dec 08, 2015 | S12: Perpetual | U12: Investment Adviser | V12: No | W12: Investment Adviser | X12: equentis.com | Y12: corporate_domain | Z12: company_firm | AA12: 100 | AB12: 97 | AC12: A - Contact First | AD12: DOMAIN::equentis.com | AF12: possible_duplicate_or_multi_category_entity | AG12: Manually verify website and contact details before outreach
A13: WEALTH FIRST INVESTMENT ADVISERS PVT. LTD. | B13: INA000005812 | C13: MR. NISHIL PANDYA | D13: CAPITOL HOUSE, 10, PARAS BUNGLOW II, NEAR CAMPUS CORNER, PRAHLADNAGAR, ANAND NAGAR | E13: nishil@wealthfirst.biz | F13: 07940240000 | G13: 07940240000 | H13: AHMEDABAD | I13: GUJARAT | J13: 380015 | K13: Capitol House, 10, Paras Bunglow II, Near Campus Corner, Prahladnagar, Anand Nagar | O13: AHMEDABAD | P13: GUJARAT | Q13: 380015 | R13: Jan 07, 2017 | S13: Perpetual | U13: Investment Adviser | V13: No | W13: Investment Adviser | X13: wealthfirst.biz | Y13: corporate_domain | Z13: company_firm | AA13: 100 | AB13: 97 | AC13: A - Contact First | AD13: DOMAIN::wealthfirst.biz | AF13: possible_duplicate_or_multi_category_entity | AG13: Manually verify website and contact details before outreach
A14: White Oak Capital Management Consultants LLP | B14: INA000008659 | C14: Riddhi Gohel | D14: Unit 6 2B, 6th Floor, Cnergy Building, Appasaheb Marathe Marg, Prabhadevi | E14: riddhi.gohel@whiteoakinvestors.com | F14: 91008976840036 | G14: 91008976840036 | H14: MUMBAI | I14: MAHARASHTRA | J14: 400025 | K14: Unit 6 2B, 6th Floor, Cnergy Building, Appasaheb Marathe Marg, Prabhadevi | L14: shweta.subramanian@whiteoakindia.com | M14: 91-00-9819155184 | N14: 91-00-9819155184 | O14: MUMBAI | P14: MAHARASHTRA | Q14: 400025 | R14: Oct 26, 2017 | S14: Perpetual | U14: Investment Adviser | V14: No | W14: Investment Adviser | X14: whiteoakinvestors.com | Y14: corporate_domain | Z14: company_firm | AA14: 100 | AB14: 97 | AC14: A - Contact First | AD14: DOMAIN::whiteoakinvestors.com | AF14: possible_duplicate_or_multi_category_entity | AG14: Manually verify website and contact details before outreach
A15: Sicomoro Advisors Private Limited | B15: INA000009834 | C15: Amit Khandelwal | D15: 102, first floor, Pharma Search House,, B.G. Kher Marg, Worli | E15: amit.khandelwal@sicomoro.in | F15: 912249636131 | G15: 912249636131 | H15: MUMBAI | I15: MAHARASHTRA | J15: 400018 | K15: 102, first floor, Pharma Search House, B.G. Kher Marg, Worli | O15: MUMBAI | P15: MAHARASHTRA | Q15: 400018 | R15: Feb 15, 2018 | S15: Perpetual | U15: Investment Adviser | V15: Yes | W15: Investment Adviser | X15: sicomoro.in | Y15: corporate_domain | Z15: company_firm | AA15: 100 | AB15: 97 | AC15: A - Contact First | AD15: DOMAIN::sicomoro.in | AF15: possible_duplicate_or_multi_category_entity | AG15: Manually verify website and contact details before outreach
A16: SWASTIKA INVESTMART LTD. | B16: INA000009843 | C16: SUNIL NYATI | D16: Office No. 104, 1st Floor, KESHAVA Commercial Building, Plot No.C 5, E Block, Bandra Kurla Complex, Opp GST Bhavan, Bandra East, | E16: COMPLIANCE@SWASTIKA.CO.IN | F16: 917310736644221 | G16: 917310736644221 | H16: MUMBAI | I16: MAHARASHTRA | J16: 400051 | K16: 48, JAORA COMPOUND, MYH ROAD | O16: INDORE | P16: MADHYA PRADESH | Q16: 452001 | R16: Feb 16, 2018 | S16: Perpetual | U16: Investment Adviser | V16: No | W16: Investment Adviser | X16: swastika.co.in | Y16: corporate_domain | Z16: company_firm | AA16: 100 | AB16: 97 | AC16: A - Contact First | AD16: DOMAIN::swastika.co.in | AF16: possible_duplicate_or_multi_category_entity | AG16: Manually verify website and contact details before outreach
A17: Pioneer Client Associates Pvt Ltd | B17: INA100010660 | C17: Rakesh Khanna | D17: 2nd floor block B vatika Towers , Golf course road sector 54 | E17: rakeshkhanna@clientassociates.com | F17: 911244995400 | G17: 911244995400 | H17: GURGAON | I17: HARYANA | J17: 122002 | K17: 2nd floor block B vatika Towers , Golf course road sector 54 | O17: GURGAON | P17: HARYANA | Q17: 122002 | R17: May 23, 2018 | S17: Perpetual | U17: Investment Adviser | V17: No | W17: Investment Adviser | X17: clientassociates.com | Y17: corporate_domain | Z17: company_firm | AA17: 100 | AB17: 97 | AC17: A - Contact First | AD17: DOMAIN::clientassociates.com | AF17: possible_duplicate_or_multi_category_entity | AG17: Manually verify website and contact details before outreach
A18: VIVEKAM FINANCIAL SERVICES PRIVATE LIMITED | B18: INA200000316 | C18: Vemuru VenkataKrishna Prasad | D18: Plot No.57, Road No.71, Jubilee Hills, Hyderabad | E18: vvkprasad@vivekam.co.in | F18: 0919848040548 | G18: 0919848040548 | H18: HYDERABAD | I18: ANDHRA PRADESH | J18: 500082 | K18: H.no.8-2-293/82/A/68, Road No.1, Jubilee Hills | O18: HYDERABAD | P18: ANDHRA PRADESH | Q18: 500033 | R18: Nov 22, 2013 | S18: Perpetual | U18: Investment Adviser | V18: No | W18: Investment Adviser | X18: vivekam.co.in | Y18: corporate_domain | Z18: company_firm | AA18: 100 | AB18: 97 | AC18: A - Contact First | AD18: DOMAIN::vivekam.co.in | AF18: possible_duplicate_or_multi_category_entity | AG18: Manually verify website and contact details before outreach
A19: CASPIAN IMPACT INVESTMENT ADVISER PRIVATE LIMITED | B19: INA200000753 | C19: VISWANATHA PRASAD | D19: 3RD FLOOR, 8-2-595/5/B/1, ROAD NO.10, BANJARA HILLS | E19: prasad@caspian.in | F19: 04066297100 | G19: 04066297100 | H19: HYDERABAD | I19: ANDHRA PRADESH | J19: 500034 | K19: 3rd floor, 8-2-595/5/B/1, Road No.10, Banjara Hills | P19: ANDHRA PRADESH | Q19: 500034 | R19: Dec 31, 2013 | S19: Perpetual | U19: Investment Adviser | V19: No | W19: Investment Adviser | X19: caspian.in | Y19: corporate_domain | Z19: company_firm | AA19: 100 | AB19: 97 | AC19: A - Contact First | AD19: DOMAIN::caspian.in | AF19: possible_duplicate_or_multi_category_entity | AG19: Manually verify website and contact details before outreach
A20: RIGHT HORIZONS INVESTMENT ADVISORY SERVICES PRIVATE LTD | B20: INA200002601 | C20: Apoorva Patil | D20: 6, AREKERE VILLAGE,, OPP, BIRTISH BIOLOGICALS, BANNAERGHATTA ROAD, | E20: complianceofficer@righthorizons.com | F20: 0919545238236 | G20: 0919545238236 | H20: BANGALORE | I20: KARNATAKA | J20: 560076 | K20: 6, AREKERE VILLAGE, OPP, BIRTISH BIOLOGICALS, BANNAERGHATTA ROAD, | O20: BANGALORE | P20: KARNATAKA | Q20: 560076 | R20: Jan 27, 2015 | S20: Perpetual | U20: Investment Adviser | V20: No | W20: Investment Adviser | X20: righthorizons.com | Y20: corporate_domain | Z20: company_firm | AA20: 100 | AB20: 97 | AC20: A - Contact First | AD20: DOMAIN::righthorizons.com | AF20: possible_duplicate_or_multi_category_entity | AG20: Manually verify website and contact details before outreach
A21: ENTRUST FAMILY OFFICE INVESTMENT ADVISORS PVT. LTD. | B21: INA200004201 | C21: Pradeep A N | D21: N0.24, 4th floor,1st Cross, Magrath Road | E21: compliance@entrust.co.in | F21: 910228041479777 | G21: 910228041479777 | H21: BANGALORE | I21: KARNATAKA | J21: 560025 | K21: NO.24, 4TH FLOOR, 1ST CROSS, MAGRATH ROAD, BEHIND GARUDA MALL | O21: BANGALORE | P21: KARNATAKA | Q21: 560025 | R21: Feb 16, 2016 | S21: Perpetual | U21: Investment Adviser | V21: No | W21: Investment Adviser | X21: entrust.co.in | Y21: corporate_domain | Z21: company_firm | AA21: 100 | AB21: 97 | AC21: A - Contact First | AD21: DOMAIN::entrust.co.in | AF21: possible_duplicate_or_multi_category_entity | AG21: Manually verify website and contact details before outreach
A22: PHI CAPITAL SERVICES LLP | B22: INA200004284 | C22: MR. P SIVARAM | D22: LG 1A, Siddhartha Chambers, Near IIT Gate, Kalu Sarai, Hauz Khas | E22: sp@phicapital.in | F22: 04428286556 | G22: 04428286556 | H22: DELHI | I22: NATIONAL CAPITAL TERRITORY OF DELHI | J22: 110016 | K22: 3rd Floor, Jayalakshmi Estates, No. 29, Haddows Road, Nungambakkam | O22: CHENNAI | P22: TAMIL NADU | Q22: 600006 | R22: Mar 04, 2016 | S22: Perpetual | U22: Investment Adviser | V22: No | W22: Investment Adviser | X22: phicapital.in | Y22: corporate_domain | Z22: company_firm | AA22: 100 | AB22: 97 | AC22: A - Contact First | AD22: DOMAIN::phicapital.in | AF22: possible_duplicate_or_multi_category_entity | AG22: Manually verify website and contact details before outreach
A23: NARNOLIA INVESTMENT ADVISORS PRIVATE LIMITED | B23: INA300005439 | C23: Anchal Narnolia | D23: Marble Arch, 236B A.J.C. Bose Road, 2nd Floor, Room No. 201 | E23: compliance@narnolia.com | F23: 0919163750006 | G23: 0919163750006 | H23: KOLKATA | I23: WEST BENGAL | J23: 700020 | K23: Marble Arch, 236B A.J.C. Bose Road, 2nd Floor, Room No. 201 | O23: KOLKATA | P23: WEST BENGAL | Q23: 700020 | R23: Aug 25, 2016 | S23: Perpetual | U23: Investment Adviser | V23: No | W23: Investment Adviser | X23: narnolia.com | Y23: corporate_domain | Z23: company_firm | AA23: 100 | AB23: 97 | AC23: A - Contact First | AD23: DOMAIN::narnolia.com | AF23: possible_duplicate_or_multi_category_entity | AG23: Manually verify website and contact details before outreach
A24: GreenEdge Wealth Services LLP | B24: INA000011574 | C24: RESHA DHAVAL HARIA | D24: The Summit Business Bay Unit No. 1123, 11th Floor, Opp. Movie Max Cinema,, Next to the Western Express Highway Metro Station,Off. Andheri Kurla Road, Gundavali, Andheri East | E24: info@greenedgewealth.com | F24: 0917400241555 | G24: 0917400241555 | H24: MUMBAI | I24: MAHARASHTRA | J24: 400093 | K24: The Summit Business Bay Unit No. 1123, 11th Floor, Opp. Movie Max Cinema, Next to the Western Express Highway Metro Station,Off. Andheri Kurla Road, Gundavali, Andheri East | O24: MUMBAI | P24: MAHARASHTRA | Q24: 400093 | R24: Aug 31, 2018 | S24: Perpetual | U24: Investment Adviser | V24: No | W24: Investment Adviser | X24: greenedgewealth.com | Y24: corporate_domain | Z24: company_firm | AA24: 100 | AB24: 97 | AC24: A - Contact First | AD24: DOMAIN::greenedgewealth.com | AF24: possible_duplicate_or_multi_category_entity | AG24: Manually verify website and contact details before outreach
A25: BUGLEROCK BHUVI INVESTMENT ADVISERS PRIVATE LIMITED | B25: INA200012674 | C25: Neha Sharma | D25: Prestige Takt, 1st Floor, No. 23,, Kasturba Road Cross, | E25: compliance.ria@buglerock.asia | F25: 918069029000 | G25: 918069029000 | H25: BANGALORE | I25: KARNATAKA | J25: 560001 | K25: Prestige Takt, 1st Floor, No. 23, Kasturba Road Cross, | O25: BANGALORE | P25: KARNATAKA | Q25: 560001 | R25: Mar 12, 2019 | S25: Perpetual | U25: Investment Adviser | V25: No | W25: Investment Adviser | X25: buglerock.asia | Y25: corporate_domain | Z25: company_firm | AA25: 100 | AB25: 97 | AC25: A - Contact First | AD25: DOMAIN::buglerock.asia | AF25: possible_duplicate_or_multi_category_entity | AG25: Manually verify website and contact details before outreach
A26: Emkay Wealth Advisory Limited | B26: INA000013961 | C26: Sonal Jadhav | D26: 7th Floor, The Ruby,, Senapati Bapat Marg, Dadar West, | E26: compliance@emkayglobal.com | F26: 9102266299299 | G26: 9102266299299 | H26: MUMBAI | I26: MAHARASHTRA | J26: 400028 | K26: Paragon Center, C-06, Ground Floor, Pandurang Budhkar Marg, Worli, | O26: MUMBAI | P26: MAHARASHTRA | Q26: 400013 | R26: Sep 16, 2019 | S26: Perpetual | U26: Investment Adviser | V26: No | W26: Investment Adviser | X26: emkayglobal.com | Y26: corporate_domain | Z26: company_firm | AA26: 100 | AB26: 97 | AC26: A - Contact First | AD26: DOMAIN::emkayglobal.com | AF26: possible_duplicate_or_multi_category_entity | AG26: Manually verify website and contact details before outreach
A27: Altinvest Capital Advisors Private Limited | B27: INA200014706 | C27: Kunal Moktan | D27: 10th Floor,SKAV Seethalakshmi, 21/22, Kasturba Road, Banglore | E27: kunal.moktan@propsharecapital.com | F27: 9108042283385 | G27: 9108042283385 | H27: BANGALORE | I27: KARNATAKA | J27: 560001 | K27: 10th Floor, SKAV, Seethalakshmi, Kasturba Road 21/22 | O27: BANGALORE | P27: KARNATAKA | Q27: 560001 | R27: May 29, 2020 | S27: Perpetual | U27: Investment Adviser | V27: No | W27: Investment Adviser | X27: propsharecapital.com | Y27: corporate_domain | Z27: company_firm | AA27: 100 | AB27: 97 | AC27: A - Contact First | AD27: DOMAIN::propsharecapital.com | AF27: possible_duplicate_or_multi_category_entity | AG27: Manually verify website and contact details before outreach
A28: Abakkus Asset Manager Private Limited | B28: INA000015729 | C28: Merlin Nadar | D28: 6th Floor,Param House,Shanti Nagar,Santacruz Chembur Link Road, Santacruz East | E28: merlin.nadar@abakkusinvest.com | F28: 0917039820098 | G28: 0917039820098 | H28: MUMBAI | I28: MAHARASHTRA | J28: 400055 | K28: 6th Floor,Param House,Shanti Nagar,Santacruz Chembur Link Road, Santacruz East | O28: MUMBAI | P28: MAHARASHTRA | Q28: 400055 | R28: Feb 03, 2021 | S28: Perpetual | U28: Investment Adviser | V28: Yes | W28: Investment Adviser | X28: abakkusinvest.com | Y28: corporate_domain | Z28: company_firm | AA28: 100 | AB28: 97 | AC28: A - Contact First | AD28: DOMAIN::abakkusinvest.com | AF28: possible_duplicate_or_multi_category_entity | AG28: Manually verify website and contact details before outreach
A29: RENAISSANCE SMART TECH PRIVATE LIMITED | B29: INA000016436 | C29: Nidhi Kamani | D29: Office No. 508, B Wing, 5th Floor,, Mittal Commercia Premises Co-op Ltd., Off. M.V. Road. Near Mittal Estate, Marol, Andheri East | E29: nidhi.kamani@renaissanceinvest.in | F29: 0919920980102 | G29: 0919920980102 | H29: MUMBAI | I29: MAHARASHTRA | J29: 400059 | K29: Office No. 508, B Wing, 5th Floor, Mittal Commercia Premises Co-op Ltd., Off. M.V. Road. Near Mittal Estate, Marol, Andheri East | O29: MUMBAI | P29: MAHARASHTRA | Q29: 400059 | R29: Nov 30, 2021 | S29: Perpetual | U29: Investment Adviser | V29: No | W29: Investment Adviser | X29: renaissanceinvest.in | Y29: corporate_domain | Z29: company_firm | AA29: 100 | AB29: 97 | AC29: A - Contact First | AD29: DOMAIN::renaissanceinvest.in | AF29: possible_duplicate_or_multi_category_entity | AG29: Manually verify website and contact details before outreach
A30: Compound Everyday Capital Management LLP | B30: INA000017198 | C30: Surbhi Sarda | D30: Sakar Bhawan 2nd floor, ATM side,, 21/4 Ratlam Kothi Main Road, Above Federal Bank | E30: surbhi@cedcapital.in | F30: 9107312510070 | G30: 9107312510070 | H30: INDORE | I30: MADHYA PRADESH | J30: 452001 | K30: Sakar Bhawan 2nd floor, ATM side, 21/4 Ratlam Kothi Main Road, Above Federal Bank | O30: INDORE | P30: MADHYA PRADESH | Q30: 452001 | R30: Sep 23, 2022 | S30: Perpetual | U30: Investment Adviser | V30: No | W30: Investment Adviser | X30: cedcapital.in | Y30: corporate_domain | Z30: company_firm | AA30: 100 | AB30: 97 | AC30: A - Contact First | AD30: DOMAIN::cedcapital.in | AF30: possible_duplicate_or_multi_category_entity | AG30: Manually verify website and contact details before outreach
A31: SINCERE SYNDICATION AND CORPORATE SERVICES LLP | B31: INA000017453 | C31: Sivaramakrishnan Raghavan | D31: Adwave Towers, 3rd Floor, Block A, No. 9, South Boag Rd, T Nagar | E31: siva@sinceresyndication.com | F31: 0919884058398 | G31: 0919884058398 | H31: CHENNAI | I31: TAMIL NADU | J31: 600017 | K31: Adwave Towers, 3rd Floor, Block A, No. 9, South Boag Rd, T Nagar | O31: CHENNAI | P31: TAMIL NADU | Q31: 600017 | R31: Dec 13, 2022 | S31: Perpetual | U31: Investment Adviser | V31: Yes | W31: Investment Adviser | X31: sinceresyndication.com | Y31: corporate_domain | Z31: company_firm | AA31: 100 | AB31: 97 | AC31: A - Contact First | AD31: DOMAIN::sinceresyndication.com | AF31: possible_duplicate_or_multi_category_entity | AG31: Manually verify website and contact details before outreach
... A33: Apricus Wealth Investment Managers LLP | B33: INA000017657 | C33: Vikrant Gupta | D33: F3/16 Model Town-2, Delhi - 110009 | E33: vikrant@apricuswealth.in | F33: 022919810302008 | G33: 022919810302008 | H33: DELHI | I33: NATIONAL CAPITAL TERRITORY OF DELHI | J33: 110009 | K33: F3/16 Model Town-2, Delhi - 110009 | O33: DELHI | P33: NATIONAL CAPITAL TERRITORY OF DELHI | Q33: 110009 | R33: Feb 20, 2023 | S33: Perpetual | U33: Investment Adviser | V33: Yes | W33: Investment Adviser | X33: apricuswealth.in | Y33: corporate_domain | Z33: company_firm | AA33: 100 | AB33: 97 | AC33: A - Contact First | AD33: DOMAIN::apricuswealth.in | AF33: possible_duplicate_or_multi_category_entity | AG33: Manually verify website and contact details before outreach
A34: Tamohara Investment Managers Private Limited | B34: INA000017842 | C34: Rajesh Kodnaney | D34: 1402, Peninsula Park, Off Veera Desai Road, Andheri West, | E34: rajesh@tamohara.net | F34: 0000000000 | G34: 0000000000 | H34: MUMBAI | I34: MAHARASHTRA | J34: 400053 | K34: 1402, Peninsula Park, , Off Veera Desai Road, Andheri West, Mumbai | L34: rajesh@tamohara.net | M34: 0-0-00000000 | N34: 0-0-00000000 | O34: MUMBAI | P34: MAHARASHTRA | Q34: 400053 | R34: Apr 20, 2023 | S34: Perpetual | U34: Investment Adviser | V34: Yes | W34: Investment Adviser | X34: tamohara.net | Y34: corporate_domain | Z34: company_firm | AA34: 100 | AB34: 97 | AC34: A - Contact First | AD34: DOMAIN::tamohara.net | AF34: possible_duplicate_or_multi_category_entity | AG34: Manually verify website and contact details before outreach
A35: DRCHOKSEY FINSERV PRIVATE LIMITED | B35: INA000017903 | C35: Maulik Trivedi | D35: C-5/6, 5th Floor, Abhishek Building, Behind Monginis Cake Factory, Off New Link Road,, Andheri West, | E35: compliance@devenchoksey.com | F35: 918104482640 | G35: 918104482640 | H35: MUMBAI | I35: MAHARASHTRA | J35: 400058 | K35: C-5/6, 5th Floor, Abhishek Building, Behind Monginis Cake Factory, Off New Link Road, Andheri West, | O35: MUMBAI | P35: MAHARASHTRA | Q35: 400058 | R35: Apr 24, 2023 | S35: Perpetual | U35: Investment Adviser | V35: Yes | W35: Investment Adviser | X35: devenchoksey.com | Y35: corporate_domain | Z35: company_firm | AA35: 100 | AB35: 97 | AC35: A - Contact First | AD35: DOMAIN::devenchoksey.com | AF35: possible_duplicate_or_multi_category_entity | AG35: Manually verify website and contact details before outreach
A36: Concept Investwell Private Limited | B36: INA000018337 | C36: Hemantkumar Desai | D36: 10/A, Union Heights, Maharana Pratap Road,, Rahul Raj Mall Lane, Dumas Road, Surat, Gujarat | E36: hemant@conceptinvestwell.com | F36: 026102206001 | G36: 026102206001 | H36: SURAT | I36: GUJARAT | J36: 395007 | K36: 10/A, Union Heights, Maharana Pratap Road, Rahul Raj Mall Lane, Dumas Road, Surat, Gujarat | O36: SURAT | P36: GUJARAT | Q36: 395007 | R36: Aug 02, 2023 | S36: Perpetual | U36: Investment Adviser | V36: No | W36: Investment Adviser | X36: conceptinvestwell.com | Y36: corporate_domain | Z36: company_firm | AA36: 100 | AB36: 97 | AC36: A - Contact First | AD36: DOMAIN::conceptinvestwell.com | AF36: possible_duplicate_or_multi_category_entity | AG36: Manually verify website and contact details before outreach
A37: CENTRICITY ADVISORY SERVICES PRIVATE LIMITED | B37: INA000018559 | C37: Arpita Hegde | D37: 203B, 2nd Floor, Tower B, Global Business Park, Mehrauli Gurgaon Road | E37: ah@centricity.co.in | F37: 00919619623465 | G37: 00919619623465 | H37: GURGAON | I37: HARYANA | J37: 122002 | K37: Unit No. 203-B, 2nd Floor, Tower B, Global Business Park, MG Road, Gurugram | O37: GURGAON | P37: HARYANA | Q37: 122002 | R37: Nov 13, 2023 | S37: Perpetual | U37: Investment Adviser | V37: No | W37: Investment Adviser | X37: centricity.co.in | Y37: corporate_domain | Z37: company_firm | AA37: 100 | AB37: 97 | AC37: A - Contact First | AD37: DOMAIN::centricity.co.in | AF37: possible_duplicate_or_multi_category_entity | AG37: Manually verify website and contact details before outreach
A38: JVT Investment Adviser LLP | B38: INA000019132 | C38: Nishant Mangla | D38: Atelier Level 1, Suite No. 3, Worldmark 2,, Aerocity, IGI Airport, South West Delhi, New Delhi, | E38: Nishant@cxpartners.in | F38: 911147640000 | G38: 911147640000 | H38: DELHI | I38: NATIONAL CAPITAL TERRITORY OF DELHI | J38: 110037 | K38: Atelier Level 1, Suite No. 3, Worldmark 2, Aerocity, IGI Airport, South West Delhi, New Delhi, | O38: DELHI | P38: NATIONAL CAPITAL TERRITORY OF DELHI | Q38: 110037 | R38: Jun 11, 2024 | S38: Perpetual | U38: Investment Adviser | V38: No | W38: Investment Adviser | X38: cxpartners.in | Y38: corporate_domain | Z38: company_firm | AA38: 100 | AB38: 97 | AC38: A - Contact First | AD38: DOMAIN::cxpartners.in | AF38: possible_duplicate_or_multi_category_entity | AG38: Manually verify website and contact details before outreach
